{
 "cells": [
  {
   "cell_type": "code",
   "execution_count": 1,
   "metadata": {},
   "outputs": [],
   "source": [
    "import pandas as pd\n",
    "import gseapy as gp"
   ]
  },
  {
   "cell_type": "code",
   "execution_count": 2,
   "metadata": {},
   "outputs": [],
   "source": [
    "gene_list = list(pd.read_csv(\"output/top100.csv\", header=None)[0])"
   ]
  },
  {
   "cell_type": "code",
   "execution_count": 4,
   "metadata": {},
   "outputs": [
    {
     "ename": "ConnectionError",
     "evalue": "HTTPConnectionPool(host='maayanlab.cloud', port=80): Max retries exceeded with url: /Enrichr/datasetStatistics (Caused by NewConnectionError('<urllib3.connection.HTTPConnection object at 0x2ab3fd81b280>: Failed to establish a new connection: [Errno 110] Connection timed out'))",
     "output_type": "error",
     "traceback": [
      "\u001b[0;31m---------------------------------------------------------------------------\u001b[0m",
      "\u001b[0;31mTimeoutError\u001b[0m                              Traceback (most recent call last)",
      "File \u001b[0;32m~/anaconda3/envs/velovgi/lib/python3.8/site-packages/urllib3/connection.py:174\u001b[0m, in \u001b[0;36mHTTPConnection._new_conn\u001b[0;34m(self)\u001b[0m\n\u001b[1;32m    173\u001b[0m \u001b[39mtry\u001b[39;00m:\n\u001b[0;32m--> 174\u001b[0m     conn \u001b[39m=\u001b[39m connection\u001b[39m.\u001b[39;49mcreate_connection(\n\u001b[1;32m    175\u001b[0m         (\u001b[39mself\u001b[39;49m\u001b[39m.\u001b[39;49m_dns_host, \u001b[39mself\u001b[39;49m\u001b[39m.\u001b[39;49mport), \u001b[39mself\u001b[39;49m\u001b[39m.\u001b[39;49mtimeout, \u001b[39m*\u001b[39;49m\u001b[39m*\u001b[39;49mextra_kw\n\u001b[1;32m    176\u001b[0m     )\n\u001b[1;32m    178\u001b[0m \u001b[39mexcept\u001b[39;00m SocketTimeout:\n",
      "File \u001b[0;32m~/anaconda3/envs/velovgi/lib/python3.8/site-packages/urllib3/util/connection.py:95\u001b[0m, in \u001b[0;36mcreate_connection\u001b[0;34m(address, timeout, source_address, socket_options)\u001b[0m\n\u001b[1;32m     94\u001b[0m \u001b[39mif\u001b[39;00m err \u001b[39mis\u001b[39;00m \u001b[39mnot\u001b[39;00m \u001b[39mNone\u001b[39;00m:\n\u001b[0;32m---> 95\u001b[0m     \u001b[39mraise\u001b[39;00m err\n\u001b[1;32m     97\u001b[0m \u001b[39mraise\u001b[39;00m socket\u001b[39m.\u001b[39merror(\u001b[39m\"\u001b[39m\u001b[39mgetaddrinfo returns an empty list\u001b[39m\u001b[39m\"\u001b[39m)\n",
      "File \u001b[0;32m~/anaconda3/envs/velovgi/lib/python3.8/site-packages/urllib3/util/connection.py:85\u001b[0m, in \u001b[0;36mcreate_connection\u001b[0;34m(address, timeout, source_address, socket_options)\u001b[0m\n\u001b[1;32m     84\u001b[0m     sock\u001b[39m.\u001b[39mbind(source_address)\n\u001b[0;32m---> 85\u001b[0m sock\u001b[39m.\u001b[39;49mconnect(sa)\n\u001b[1;32m     86\u001b[0m \u001b[39mreturn\u001b[39;00m sock\n",
      "\u001b[0;31mTimeoutError\u001b[0m: [Errno 110] Connection timed out",
      "\nDuring handling of the above exception, another exception occurred:\n",
      "\u001b[0;31mNewConnectionError\u001b[0m                        Traceback (most recent call last)",
      "File \u001b[0;32m~/anaconda3/envs/velovgi/lib/python3.8/site-packages/urllib3/connectionpool.py:703\u001b[0m, in \u001b[0;36mHTTPConnectionPool.urlopen\u001b[0;34m(self, method, url, body, headers, retries, redirect, assert_same_host, timeout, pool_timeout, release_conn, chunked, body_pos, **response_kw)\u001b[0m\n\u001b[1;32m    702\u001b[0m \u001b[39m# Make the request on the httplib connection object.\u001b[39;00m\n\u001b[0;32m--> 703\u001b[0m httplib_response \u001b[39m=\u001b[39m \u001b[39mself\u001b[39;49m\u001b[39m.\u001b[39;49m_make_request(\n\u001b[1;32m    704\u001b[0m     conn,\n\u001b[1;32m    705\u001b[0m     method,\n\u001b[1;32m    706\u001b[0m     url,\n\u001b[1;32m    707\u001b[0m     timeout\u001b[39m=\u001b[39;49mtimeout_obj,\n\u001b[1;32m    708\u001b[0m     body\u001b[39m=\u001b[39;49mbody,\n\u001b[1;32m    709\u001b[0m     headers\u001b[39m=\u001b[39;49mheaders,\n\u001b[1;32m    710\u001b[0m     chunked\u001b[39m=\u001b[39;49mchunked,\n\u001b[1;32m    711\u001b[0m )\n\u001b[1;32m    713\u001b[0m \u001b[39m# If we're going to release the connection in ``finally:``, then\u001b[39;00m\n\u001b[1;32m    714\u001b[0m \u001b[39m# the response doesn't need to know about the connection. Otherwise\u001b[39;00m\n\u001b[1;32m    715\u001b[0m \u001b[39m# it will also try to release it and we'll have a double-release\u001b[39;00m\n\u001b[1;32m    716\u001b[0m \u001b[39m# mess.\u001b[39;00m\n",
      "File \u001b[0;32m~/anaconda3/envs/velovgi/lib/python3.8/site-packages/urllib3/connectionpool.py:398\u001b[0m, in \u001b[0;36mHTTPConnectionPool._make_request\u001b[0;34m(self, conn, method, url, timeout, chunked, **httplib_request_kw)\u001b[0m\n\u001b[1;32m    397\u001b[0m     \u001b[39melse\u001b[39;00m:\n\u001b[0;32m--> 398\u001b[0m         conn\u001b[39m.\u001b[39;49mrequest(method, url, \u001b[39m*\u001b[39;49m\u001b[39m*\u001b[39;49mhttplib_request_kw)\n\u001b[1;32m    400\u001b[0m \u001b[39m# We are swallowing BrokenPipeError (errno.EPIPE) since the server is\u001b[39;00m\n\u001b[1;32m    401\u001b[0m \u001b[39m# legitimately able to close the connection after sending a valid response.\u001b[39;00m\n\u001b[1;32m    402\u001b[0m \u001b[39m# With this behaviour, the received response is still readable.\u001b[39;00m\n",
      "File \u001b[0;32m~/anaconda3/envs/velovgi/lib/python3.8/site-packages/urllib3/connection.py:244\u001b[0m, in \u001b[0;36mHTTPConnection.request\u001b[0;34m(self, method, url, body, headers)\u001b[0m\n\u001b[1;32m    243\u001b[0m     headers[\u001b[39m\"\u001b[39m\u001b[39mUser-Agent\u001b[39m\u001b[39m\"\u001b[39m] \u001b[39m=\u001b[39m _get_default_user_agent()\n\u001b[0;32m--> 244\u001b[0m \u001b[39msuper\u001b[39;49m(HTTPConnection, \u001b[39mself\u001b[39;49m)\u001b[39m.\u001b[39;49mrequest(method, url, body\u001b[39m=\u001b[39;49mbody, headers\u001b[39m=\u001b[39;49mheaders)\n",
      "File \u001b[0;32m~/anaconda3/envs/velovgi/lib/python3.8/http/client.py:1256\u001b[0m, in \u001b[0;36mHTTPConnection.request\u001b[0;34m(self, method, url, body, headers, encode_chunked)\u001b[0m\n\u001b[1;32m   1255\u001b[0m \u001b[39m\u001b[39m\u001b[39m\"\"\"Send a complete request to the server.\"\"\"\u001b[39;00m\n\u001b[0;32m-> 1256\u001b[0m \u001b[39mself\u001b[39;49m\u001b[39m.\u001b[39;49m_send_request(method, url, body, headers, encode_chunked)\n",
      "File \u001b[0;32m~/anaconda3/envs/velovgi/lib/python3.8/http/client.py:1302\u001b[0m, in \u001b[0;36mHTTPConnection._send_request\u001b[0;34m(self, method, url, body, headers, encode_chunked)\u001b[0m\n\u001b[1;32m   1301\u001b[0m     body \u001b[39m=\u001b[39m _encode(body, \u001b[39m'\u001b[39m\u001b[39mbody\u001b[39m\u001b[39m'\u001b[39m)\n\u001b[0;32m-> 1302\u001b[0m \u001b[39mself\u001b[39;49m\u001b[39m.\u001b[39;49mendheaders(body, encode_chunked\u001b[39m=\u001b[39;49mencode_chunked)\n",
      "File \u001b[0;32m~/anaconda3/envs/velovgi/lib/python3.8/http/client.py:1251\u001b[0m, in \u001b[0;36mHTTPConnection.endheaders\u001b[0;34m(self, message_body, encode_chunked)\u001b[0m\n\u001b[1;32m   1250\u001b[0m     \u001b[39mraise\u001b[39;00m CannotSendHeader()\n\u001b[0;32m-> 1251\u001b[0m \u001b[39mself\u001b[39;49m\u001b[39m.\u001b[39;49m_send_output(message_body, encode_chunked\u001b[39m=\u001b[39;49mencode_chunked)\n",
      "File \u001b[0;32m~/anaconda3/envs/velovgi/lib/python3.8/http/client.py:1011\u001b[0m, in \u001b[0;36mHTTPConnection._send_output\u001b[0;34m(self, message_body, encode_chunked)\u001b[0m\n\u001b[1;32m   1010\u001b[0m \u001b[39mdel\u001b[39;00m \u001b[39mself\u001b[39m\u001b[39m.\u001b[39m_buffer[:]\n\u001b[0;32m-> 1011\u001b[0m \u001b[39mself\u001b[39;49m\u001b[39m.\u001b[39;49msend(msg)\n\u001b[1;32m   1013\u001b[0m \u001b[39mif\u001b[39;00m message_body \u001b[39mis\u001b[39;00m \u001b[39mnot\u001b[39;00m \u001b[39mNone\u001b[39;00m:\n\u001b[1;32m   1014\u001b[0m \n\u001b[1;32m   1015\u001b[0m     \u001b[39m# create a consistent interface to message_body\u001b[39;00m\n",
      "File \u001b[0;32m~/anaconda3/envs/velovgi/lib/python3.8/http/client.py:951\u001b[0m, in \u001b[0;36mHTTPConnection.send\u001b[0;34m(self, data)\u001b[0m\n\u001b[1;32m    950\u001b[0m \u001b[39mif\u001b[39;00m \u001b[39mself\u001b[39m\u001b[39m.\u001b[39mauto_open:\n\u001b[0;32m--> 951\u001b[0m     \u001b[39mself\u001b[39;49m\u001b[39m.\u001b[39;49mconnect()\n\u001b[1;32m    952\u001b[0m \u001b[39melse\u001b[39;00m:\n",
      "File \u001b[0;32m~/anaconda3/envs/velovgi/lib/python3.8/site-packages/urllib3/connection.py:205\u001b[0m, in \u001b[0;36mHTTPConnection.connect\u001b[0;34m(self)\u001b[0m\n\u001b[1;32m    204\u001b[0m \u001b[39mdef\u001b[39;00m \u001b[39mconnect\u001b[39m(\u001b[39mself\u001b[39m):\n\u001b[0;32m--> 205\u001b[0m     conn \u001b[39m=\u001b[39m \u001b[39mself\u001b[39;49m\u001b[39m.\u001b[39;49m_new_conn()\n\u001b[1;32m    206\u001b[0m     \u001b[39mself\u001b[39m\u001b[39m.\u001b[39m_prepare_conn(conn)\n",
      "File \u001b[0;32m~/anaconda3/envs/velovgi/lib/python3.8/site-packages/urllib3/connection.py:186\u001b[0m, in \u001b[0;36mHTTPConnection._new_conn\u001b[0;34m(self)\u001b[0m\n\u001b[1;32m    185\u001b[0m \u001b[39mexcept\u001b[39;00m SocketError \u001b[39mas\u001b[39;00m e:\n\u001b[0;32m--> 186\u001b[0m     \u001b[39mraise\u001b[39;00m NewConnectionError(\n\u001b[1;32m    187\u001b[0m         \u001b[39mself\u001b[39m, \u001b[39m\"\u001b[39m\u001b[39mFailed to establish a new connection: \u001b[39m\u001b[39m%s\u001b[39;00m\u001b[39m\"\u001b[39m \u001b[39m%\u001b[39m e\n\u001b[1;32m    188\u001b[0m     )\n\u001b[1;32m    190\u001b[0m \u001b[39mreturn\u001b[39;00m conn\n",
      "\u001b[0;31mNewConnectionError\u001b[0m: <urllib3.connection.HTTPConnection object at 0x2ab3fd81b280>: Failed to establish a new connection: [Errno 110] Connection timed out",
      "\nDuring handling of the above exception, another exception occurred:\n",
      "\u001b[0;31mMaxRetryError\u001b[0m                             Traceback (most recent call last)",
      "File \u001b[0;32m~/anaconda3/envs/velovgi/lib/python3.8/site-packages/requests/adapters.py:487\u001b[0m, in \u001b[0;36mHTTPAdapter.send\u001b[0;34m(self, request, stream, timeout, verify, cert, proxies)\u001b[0m\n\u001b[1;32m    486\u001b[0m \u001b[39mtry\u001b[39;00m:\n\u001b[0;32m--> 487\u001b[0m     resp \u001b[39m=\u001b[39m conn\u001b[39m.\u001b[39;49murlopen(\n\u001b[1;32m    488\u001b[0m         method\u001b[39m=\u001b[39;49mrequest\u001b[39m.\u001b[39;49mmethod,\n\u001b[1;32m    489\u001b[0m         url\u001b[39m=\u001b[39;49murl,\n\u001b[1;32m    490\u001b[0m         body\u001b[39m=\u001b[39;49mrequest\u001b[39m.\u001b[39;49mbody,\n\u001b[1;32m    491\u001b[0m         headers\u001b[39m=\u001b[39;49mrequest\u001b[39m.\u001b[39;49mheaders,\n\u001b[1;32m    492\u001b[0m         redirect\u001b[39m=\u001b[39;49m\u001b[39mFalse\u001b[39;49;00m,\n\u001b[1;32m    493\u001b[0m         assert_same_host\u001b[39m=\u001b[39;49m\u001b[39mFalse\u001b[39;49;00m,\n\u001b[1;32m    494\u001b[0m         preload_content\u001b[39m=\u001b[39;49m\u001b[39mFalse\u001b[39;49;00m,\n\u001b[1;32m    495\u001b[0m         decode_content\u001b[39m=\u001b[39;49m\u001b[39mFalse\u001b[39;49;00m,\n\u001b[1;32m    496\u001b[0m         retries\u001b[39m=\u001b[39;49m\u001b[39mself\u001b[39;49m\u001b[39m.\u001b[39;49mmax_retries,\n\u001b[1;32m    497\u001b[0m         timeout\u001b[39m=\u001b[39;49mtimeout,\n\u001b[1;32m    498\u001b[0m         chunked\u001b[39m=\u001b[39;49mchunked,\n\u001b[1;32m    499\u001b[0m     )\n\u001b[1;32m    501\u001b[0m \u001b[39mexcept\u001b[39;00m (ProtocolError, \u001b[39mOSError\u001b[39;00m) \u001b[39mas\u001b[39;00m err:\n",
      "File \u001b[0;32m~/anaconda3/envs/velovgi/lib/python3.8/site-packages/urllib3/connectionpool.py:815\u001b[0m, in \u001b[0;36mHTTPConnectionPool.urlopen\u001b[0;34m(self, method, url, body, headers, retries, redirect, assert_same_host, timeout, pool_timeout, release_conn, chunked, body_pos, **response_kw)\u001b[0m\n\u001b[1;32m    812\u001b[0m     log\u001b[39m.\u001b[39mwarning(\n\u001b[1;32m    813\u001b[0m         \u001b[39m\"\u001b[39m\u001b[39mRetrying (\u001b[39m\u001b[39m%r\u001b[39;00m\u001b[39m) after connection broken by \u001b[39m\u001b[39m'\u001b[39m\u001b[39m%r\u001b[39;00m\u001b[39m'\u001b[39m\u001b[39m: \u001b[39m\u001b[39m%s\u001b[39;00m\u001b[39m\"\u001b[39m, retries, err, url\n\u001b[1;32m    814\u001b[0m     )\n\u001b[0;32m--> 815\u001b[0m     \u001b[39mreturn\u001b[39;00m \u001b[39mself\u001b[39;49m\u001b[39m.\u001b[39;49murlopen(\n\u001b[1;32m    816\u001b[0m         method,\n\u001b[1;32m    817\u001b[0m         url,\n\u001b[1;32m    818\u001b[0m         body,\n\u001b[1;32m    819\u001b[0m         headers,\n\u001b[1;32m    820\u001b[0m         retries,\n\u001b[1;32m    821\u001b[0m         redirect,\n\u001b[1;32m    822\u001b[0m         assert_same_host,\n\u001b[1;32m    823\u001b[0m         timeout\u001b[39m=\u001b[39;49mtimeout,\n\u001b[1;32m    824\u001b[0m         pool_timeout\u001b[39m=\u001b[39;49mpool_timeout,\n\u001b[1;32m    825\u001b[0m         release_conn\u001b[39m=\u001b[39;49mrelease_conn,\n\u001b[1;32m    826\u001b[0m         chunked\u001b[39m=\u001b[39;49mchunked,\n\u001b[1;32m    827\u001b[0m         body_pos\u001b[39m=\u001b[39;49mbody_pos,\n\u001b[1;32m    828\u001b[0m         \u001b[39m*\u001b[39;49m\u001b[39m*\u001b[39;49mresponse_kw\n\u001b[1;32m    829\u001b[0m     )\n\u001b[1;32m    831\u001b[0m \u001b[39m# Handle redirect?\u001b[39;00m\n",
      "File \u001b[0;32m~/anaconda3/envs/velovgi/lib/python3.8/site-packages/urllib3/connectionpool.py:815\u001b[0m, in \u001b[0;36mHTTPConnectionPool.urlopen\u001b[0;34m(self, method, url, body, headers, retries, redirect, assert_same_host, timeout, pool_timeout, release_conn, chunked, body_pos, **response_kw)\u001b[0m\n\u001b[1;32m    812\u001b[0m     log\u001b[39m.\u001b[39mwarning(\n\u001b[1;32m    813\u001b[0m         \u001b[39m\"\u001b[39m\u001b[39mRetrying (\u001b[39m\u001b[39m%r\u001b[39;00m\u001b[39m) after connection broken by \u001b[39m\u001b[39m'\u001b[39m\u001b[39m%r\u001b[39;00m\u001b[39m'\u001b[39m\u001b[39m: \u001b[39m\u001b[39m%s\u001b[39;00m\u001b[39m\"\u001b[39m, retries, err, url\n\u001b[1;32m    814\u001b[0m     )\n\u001b[0;32m--> 815\u001b[0m     \u001b[39mreturn\u001b[39;00m \u001b[39mself\u001b[39;49m\u001b[39m.\u001b[39;49murlopen(\n\u001b[1;32m    816\u001b[0m         method,\n\u001b[1;32m    817\u001b[0m         url,\n\u001b[1;32m    818\u001b[0m         body,\n\u001b[1;32m    819\u001b[0m         headers,\n\u001b[1;32m    820\u001b[0m         retries,\n\u001b[1;32m    821\u001b[0m         redirect,\n\u001b[1;32m    822\u001b[0m         assert_same_host,\n\u001b[1;32m    823\u001b[0m         timeout\u001b[39m=\u001b[39;49mtimeout,\n\u001b[1;32m    824\u001b[0m         pool_timeout\u001b[39m=\u001b[39;49mpool_timeout,\n\u001b[1;32m    825\u001b[0m         release_conn\u001b[39m=\u001b[39;49mrelease_conn,\n\u001b[1;32m    826\u001b[0m         chunked\u001b[39m=\u001b[39;49mchunked,\n\u001b[1;32m    827\u001b[0m         body_pos\u001b[39m=\u001b[39;49mbody_pos,\n\u001b[1;32m    828\u001b[0m         \u001b[39m*\u001b[39;49m\u001b[39m*\u001b[39;49mresponse_kw\n\u001b[1;32m    829\u001b[0m     )\n\u001b[1;32m    831\u001b[0m \u001b[39m# Handle redirect?\u001b[39;00m\n",
      "    \u001b[0;31m[... skipping similar frames: HTTPConnectionPool.urlopen at line 815 (2 times)]\u001b[0m\n",
      "File \u001b[0;32m~/anaconda3/envs/velovgi/lib/python3.8/site-packages/urllib3/connectionpool.py:815\u001b[0m, in \u001b[0;36mHTTPConnectionPool.urlopen\u001b[0;34m(self, method, url, body, headers, retries, redirect, assert_same_host, timeout, pool_timeout, release_conn, chunked, body_pos, **response_kw)\u001b[0m\n\u001b[1;32m    812\u001b[0m     log\u001b[39m.\u001b[39mwarning(\n\u001b[1;32m    813\u001b[0m         \u001b[39m\"\u001b[39m\u001b[39mRetrying (\u001b[39m\u001b[39m%r\u001b[39;00m\u001b[39m) after connection broken by \u001b[39m\u001b[39m'\u001b[39m\u001b[39m%r\u001b[39;00m\u001b[39m'\u001b[39m\u001b[39m: \u001b[39m\u001b[39m%s\u001b[39;00m\u001b[39m\"\u001b[39m, retries, err, url\n\u001b[1;32m    814\u001b[0m     )\n\u001b[0;32m--> 815\u001b[0m     \u001b[39mreturn\u001b[39;00m \u001b[39mself\u001b[39;49m\u001b[39m.\u001b[39;49murlopen(\n\u001b[1;32m    816\u001b[0m         method,\n\u001b[1;32m    817\u001b[0m         url,\n\u001b[1;32m    818\u001b[0m         body,\n\u001b[1;32m    819\u001b[0m         headers,\n\u001b[1;32m    820\u001b[0m         retries,\n\u001b[1;32m    821\u001b[0m         redirect,\n\u001b[1;32m    822\u001b[0m         assert_same_host,\n\u001b[1;32m    823\u001b[0m         timeout\u001b[39m=\u001b[39;49mtimeout,\n\u001b[1;32m    824\u001b[0m         pool_timeout\u001b[39m=\u001b[39;49mpool_timeout,\n\u001b[1;32m    825\u001b[0m         release_conn\u001b[39m=\u001b[39;49mrelease_conn,\n\u001b[1;32m    826\u001b[0m         chunked\u001b[39m=\u001b[39;49mchunked,\n\u001b[1;32m    827\u001b[0m         body_pos\u001b[39m=\u001b[39;49mbody_pos,\n\u001b[1;32m    828\u001b[0m         \u001b[39m*\u001b[39;49m\u001b[39m*\u001b[39;49mresponse_kw\n\u001b[1;32m    829\u001b[0m     )\n\u001b[1;32m    831\u001b[0m \u001b[39m# Handle redirect?\u001b[39;00m\n",
      "File \u001b[0;32m~/anaconda3/envs/velovgi/lib/python3.8/site-packages/urllib3/connectionpool.py:787\u001b[0m, in \u001b[0;36mHTTPConnectionPool.urlopen\u001b[0;34m(self, method, url, body, headers, retries, redirect, assert_same_host, timeout, pool_timeout, release_conn, chunked, body_pos, **response_kw)\u001b[0m\n\u001b[1;32m    785\u001b[0m     e \u001b[39m=\u001b[39m ProtocolError(\u001b[39m\"\u001b[39m\u001b[39mConnection aborted.\u001b[39m\u001b[39m\"\u001b[39m, e)\n\u001b[0;32m--> 787\u001b[0m retries \u001b[39m=\u001b[39m retries\u001b[39m.\u001b[39;49mincrement(\n\u001b[1;32m    788\u001b[0m     method, url, error\u001b[39m=\u001b[39;49me, _pool\u001b[39m=\u001b[39;49m\u001b[39mself\u001b[39;49m, _stacktrace\u001b[39m=\u001b[39;49msys\u001b[39m.\u001b[39;49mexc_info()[\u001b[39m2\u001b[39;49m]\n\u001b[1;32m    789\u001b[0m )\n\u001b[1;32m    790\u001b[0m retries\u001b[39m.\u001b[39msleep()\n",
      "File \u001b[0;32m~/anaconda3/envs/velovgi/lib/python3.8/site-packages/urllib3/util/retry.py:592\u001b[0m, in \u001b[0;36mRetry.increment\u001b[0;34m(self, method, url, response, error, _pool, _stacktrace)\u001b[0m\n\u001b[1;32m    591\u001b[0m \u001b[39mif\u001b[39;00m new_retry\u001b[39m.\u001b[39mis_exhausted():\n\u001b[0;32m--> 592\u001b[0m     \u001b[39mraise\u001b[39;00m MaxRetryError(_pool, url, error \u001b[39mor\u001b[39;00m ResponseError(cause))\n\u001b[1;32m    594\u001b[0m log\u001b[39m.\u001b[39mdebug(\u001b[39m\"\u001b[39m\u001b[39mIncremented Retry for (url=\u001b[39m\u001b[39m'\u001b[39m\u001b[39m%s\u001b[39;00m\u001b[39m'\u001b[39m\u001b[39m): \u001b[39m\u001b[39m%r\u001b[39;00m\u001b[39m\"\u001b[39m, url, new_retry)\n",
      "\u001b[0;31mMaxRetryError\u001b[0m: HTTPConnectionPool(host='maayanlab.cloud', port=80): Max retries exceeded with url: /Enrichr/datasetStatistics (Caused by NewConnectionError('<urllib3.connection.HTTPConnection object at 0x2ab3fd81b280>: Failed to establish a new connection: [Errno 110] Connection timed out'))",
      "\nDuring handling of the above exception, another exception occurred:\n",
      "\u001b[0;31mConnectionError\u001b[0m                           Traceback (most recent call last)",
      "Cell \u001b[0;32mIn[4], line 1\u001b[0m\n\u001b[0;32m----> 1\u001b[0m enrichment_df \u001b[39m=\u001b[39m gp\u001b[39m.\u001b[39;49menrichr(gene_list, gene_sets\u001b[39m=\u001b[39;49m\u001b[39m\"\u001b[39;49m\u001b[39mKEGG_2019_Mouse\u001b[39;49m\u001b[39m\"\u001b[39;49m)\u001b[39m.\u001b[39mres2d \u001b[39m# kegg只需要搜索1个数据库即可\u001b[39;00m\n\u001b[1;32m      2\u001b[0m enrichment_df\u001b[39m.\u001b[39mto_csv(\u001b[39m\"\u001b[39m\u001b[39moutput/top100_kegg.csv\u001b[39m\u001b[39m\"\u001b[39m) \u001b[39m# 保存DataFrame\u001b[39;00m\n\u001b[1;32m      3\u001b[0m gp\u001b[39m.\u001b[39mdotplot(enrichment_df, figsize\u001b[39m=\u001b[39m(\u001b[39m3\u001b[39m,\u001b[39m5\u001b[39m)) \u001b[39m# 保存kegg结果图\u001b[39;00m\n",
      "File \u001b[0;32m~/anaconda3/envs/velovgi/lib/python3.8/site-packages/gseapy/__init__.py:536\u001b[0m, in \u001b[0;36menrichr\u001b[0;34m(gene_list, gene_sets, organism, outdir, background, cutoff, format, figsize, top_term, no_plot, verbose)\u001b[0m\n\u001b[1;32m    534\u001b[0m \u001b[39m# set organism\u001b[39;00m\n\u001b[1;32m    535\u001b[0m enr\u001b[39m.\u001b[39mset_organism()\n\u001b[0;32m--> 536\u001b[0m enr\u001b[39m.\u001b[39;49mrun()\n\u001b[1;32m    538\u001b[0m \u001b[39mreturn\u001b[39;00m enr\n",
      "File \u001b[0;32m~/anaconda3/envs/velovgi/lib/python3.8/site-packages/gseapy/enrichr.py:570\u001b[0m, in \u001b[0;36mEnrichr.run\u001b[0;34m(self)\u001b[0m\n\u001b[1;32m    567\u001b[0m genes_list \u001b[39m=\u001b[39m \u001b[39mself\u001b[39m\u001b[39m.\u001b[39mparse_genelists()\n\u001b[1;32m    569\u001b[0m \u001b[39m# self._logger.info(\"Connecting to Enrichr Server to get latest library names\")\u001b[39;00m\n\u001b[0;32m--> 570\u001b[0m gss \u001b[39m=\u001b[39m \u001b[39mself\u001b[39;49m\u001b[39m.\u001b[39;49mparse_genesets()\n\u001b[1;32m    571\u001b[0m \u001b[39mif\u001b[39;00m \u001b[39mlen\u001b[39m(gss) \u001b[39m<\u001b[39m \u001b[39m1\u001b[39m:\n\u001b[1;32m    572\u001b[0m     \u001b[39mself\u001b[39m\u001b[39m.\u001b[39m_logger\u001b[39m.\u001b[39merror(\n\u001b[1;32m    573\u001b[0m         \u001b[39m\"\u001b[39m\u001b[39mNone of your input gene set matched ! \u001b[39m\u001b[39m%s\u001b[39;00m\u001b[39m\"\u001b[39m \u001b[39m%\u001b[39m \u001b[39mself\u001b[39m\u001b[39m.\u001b[39mgene_sets\n\u001b[1;32m    574\u001b[0m     )\n",
      "File \u001b[0;32m~/anaconda3/envs/velovgi/lib/python3.8/site-packages/gseapy/enrichr.py:141\u001b[0m, in \u001b[0;36mEnrichr.parse_genesets\u001b[0;34m(self, gene_sets)\u001b[0m\n\u001b[1;32m    139\u001b[0m \u001b[39m# if all local gmts (local mode), skip connect to enrichr server\u001b[39;00m\n\u001b[1;32m    140\u001b[0m \u001b[39mif\u001b[39;00m \u001b[39mnot\u001b[39;00m \u001b[39mall\u001b[39m([\u001b[39misinstance\u001b[39m(g, \u001b[39mdict\u001b[39m) \u001b[39mfor\u001b[39;00m g \u001b[39min\u001b[39;00m gss]):\n\u001b[0;32m--> 141\u001b[0m     enrichr_library \u001b[39m=\u001b[39m \u001b[39mself\u001b[39;49m\u001b[39m.\u001b[39;49mget_libraries()\n\u001b[1;32m    143\u001b[0m \u001b[39m# check enrichr libraries are valid\u001b[39;00m\n\u001b[1;32m    144\u001b[0m \u001b[39mfor\u001b[39;00m n, g \u001b[39min\u001b[39;00m \u001b[39mzip\u001b[39m(\u001b[39mself\u001b[39m\u001b[39m.\u001b[39m_gs_name, gss):\n",
      "File \u001b[0;32m~/anaconda3/envs/velovgi/lib/python3.8/site-packages/gseapy/enrichr.py:366\u001b[0m, in \u001b[0;36mEnrichr.get_libraries\u001b[0;34m(self)\u001b[0m\n\u001b[1;32m    364\u001b[0m lib_url \u001b[39m=\u001b[39m \u001b[39m\"\u001b[39m\u001b[39m%s\u001b[39;00m\u001b[39m/\u001b[39m\u001b[39m%s\u001b[39;00m\u001b[39m/datasetStatistics\u001b[39m\u001b[39m\"\u001b[39m \u001b[39m%\u001b[39m (\u001b[39mself\u001b[39m\u001b[39m.\u001b[39mENRICHR_URL, \u001b[39mself\u001b[39m\u001b[39m.\u001b[39m_organism)\n\u001b[1;32m    365\u001b[0m s \u001b[39m=\u001b[39m retry(num\u001b[39m=\u001b[39m\u001b[39m5\u001b[39m)\n\u001b[0;32m--> 366\u001b[0m response \u001b[39m=\u001b[39m s\u001b[39m.\u001b[39;49mget(lib_url, verify\u001b[39m=\u001b[39;49m\u001b[39mTrue\u001b[39;49;00m)\n\u001b[1;32m    367\u001b[0m \u001b[39mif\u001b[39;00m \u001b[39mnot\u001b[39;00m response\u001b[39m.\u001b[39mok:\n\u001b[1;32m    368\u001b[0m     \u001b[39mraise\u001b[39;00m \u001b[39mException\u001b[39;00m(\u001b[39m\"\u001b[39m\u001b[39mError getting the Enrichr libraries\u001b[39m\u001b[39m\"\u001b[39m)\n",
      "File \u001b[0;32m~/anaconda3/envs/velovgi/lib/python3.8/site-packages/requests/sessions.py:600\u001b[0m, in \u001b[0;36mSession.get\u001b[0;34m(self, url, **kwargs)\u001b[0m\n\u001b[1;32m    592\u001b[0m \u001b[39m\u001b[39m\u001b[39mr\u001b[39m\u001b[39m\"\"\"Sends a GET request. Returns :class:`Response` object.\u001b[39;00m\n\u001b[1;32m    593\u001b[0m \n\u001b[1;32m    594\u001b[0m \u001b[39m:param url: URL for the new :class:`Request` object.\u001b[39;00m\n\u001b[1;32m    595\u001b[0m \u001b[39m:param \\*\\*kwargs: Optional arguments that ``request`` takes.\u001b[39;00m\n\u001b[1;32m    596\u001b[0m \u001b[39m:rtype: requests.Response\u001b[39;00m\n\u001b[1;32m    597\u001b[0m \u001b[39m\"\"\"\u001b[39;00m\n\u001b[1;32m    599\u001b[0m kwargs\u001b[39m.\u001b[39msetdefault(\u001b[39m\"\u001b[39m\u001b[39mallow_redirects\u001b[39m\u001b[39m\"\u001b[39m, \u001b[39mTrue\u001b[39;00m)\n\u001b[0;32m--> 600\u001b[0m \u001b[39mreturn\u001b[39;00m \u001b[39mself\u001b[39;49m\u001b[39m.\u001b[39;49mrequest(\u001b[39m\"\u001b[39;49m\u001b[39mGET\u001b[39;49m\u001b[39m\"\u001b[39;49m, url, \u001b[39m*\u001b[39;49m\u001b[39m*\u001b[39;49mkwargs)\n",
      "File \u001b[0;32m~/anaconda3/envs/velovgi/lib/python3.8/site-packages/requests/sessions.py:587\u001b[0m, in \u001b[0;36mSession.request\u001b[0;34m(self, method, url, params, data, headers, cookies, files, auth, timeout, allow_redirects, proxies, hooks, stream, verify, cert, json)\u001b[0m\n\u001b[1;32m    582\u001b[0m send_kwargs \u001b[39m=\u001b[39m {\n\u001b[1;32m    583\u001b[0m     \u001b[39m\"\u001b[39m\u001b[39mtimeout\u001b[39m\u001b[39m\"\u001b[39m: timeout,\n\u001b[1;32m    584\u001b[0m     \u001b[39m\"\u001b[39m\u001b[39mallow_redirects\u001b[39m\u001b[39m\"\u001b[39m: allow_redirects,\n\u001b[1;32m    585\u001b[0m }\n\u001b[1;32m    586\u001b[0m send_kwargs\u001b[39m.\u001b[39mupdate(settings)\n\u001b[0;32m--> 587\u001b[0m resp \u001b[39m=\u001b[39m \u001b[39mself\u001b[39;49m\u001b[39m.\u001b[39;49msend(prep, \u001b[39m*\u001b[39;49m\u001b[39m*\u001b[39;49msend_kwargs)\n\u001b[1;32m    589\u001b[0m \u001b[39mreturn\u001b[39;00m resp\n",
      "File \u001b[0;32m~/anaconda3/envs/velovgi/lib/python3.8/site-packages/requests/sessions.py:701\u001b[0m, in \u001b[0;36mSession.send\u001b[0;34m(self, request, **kwargs)\u001b[0m\n\u001b[1;32m    698\u001b[0m start \u001b[39m=\u001b[39m preferred_clock()\n\u001b[1;32m    700\u001b[0m \u001b[39m# Send the request\u001b[39;00m\n\u001b[0;32m--> 701\u001b[0m r \u001b[39m=\u001b[39m adapter\u001b[39m.\u001b[39;49msend(request, \u001b[39m*\u001b[39;49m\u001b[39m*\u001b[39;49mkwargs)\n\u001b[1;32m    703\u001b[0m \u001b[39m# Total elapsed time of the request (approximately)\u001b[39;00m\n\u001b[1;32m    704\u001b[0m elapsed \u001b[39m=\u001b[39m preferred_clock() \u001b[39m-\u001b[39m start\n",
      "File \u001b[0;32m~/anaconda3/envs/velovgi/lib/python3.8/site-packages/requests/adapters.py:520\u001b[0m, in \u001b[0;36mHTTPAdapter.send\u001b[0;34m(self, request, stream, timeout, verify, cert, proxies)\u001b[0m\n\u001b[1;32m    516\u001b[0m     \u001b[39mif\u001b[39;00m \u001b[39misinstance\u001b[39m(e\u001b[39m.\u001b[39mreason, _SSLError):\n\u001b[1;32m    517\u001b[0m         \u001b[39m# This branch is for urllib3 v1.22 and later.\u001b[39;00m\n\u001b[1;32m    518\u001b[0m         \u001b[39mraise\u001b[39;00m SSLError(e, request\u001b[39m=\u001b[39mrequest)\n\u001b[0;32m--> 520\u001b[0m     \u001b[39mraise\u001b[39;00m \u001b[39mConnectionError\u001b[39;00m(e, request\u001b[39m=\u001b[39mrequest)\n\u001b[1;32m    522\u001b[0m \u001b[39mexcept\u001b[39;00m ClosedPoolError \u001b[39mas\u001b[39;00m e:\n\u001b[1;32m    523\u001b[0m     \u001b[39mraise\u001b[39;00m \u001b[39mConnectionError\u001b[39;00m(e, request\u001b[39m=\u001b[39mrequest)\n",
      "\u001b[0;31mConnectionError\u001b[0m: HTTPConnectionPool(host='maayanlab.cloud', port=80): Max retries exceeded with url: /Enrichr/datasetStatistics (Caused by NewConnectionError('<urllib3.connection.HTTPConnection object at 0x2ab3fd81b280>: Failed to establish a new connection: [Errno 110] Connection timed out'))"
     ]
    }
   ],
   "source": [
    "enrichment_df = gp.enrichr(gene_list, gene_sets=\"KEGG_2019_Mouse\").res2d # kegg只需要搜索1个数据库即可\n",
    "enrichment_df.to_csv(\"output/top100_kegg.csv\") # 保存DataFrame\n",
    "gp.dotplot(enrichment_df, figsize=(3,5)) # 保存kegg结果图"
   ]
  }
 ],
 "metadata": {
  "kernelspec": {
   "display_name": "velovgi",
   "language": "python",
   "name": "python3"
  },
  "language_info": {
   "codemirror_mode": {
    "name": "ipython",
    "version": 3
   },
   "file_extension": ".py",
   "mimetype": "text/x-python",
   "name": "python",
   "nbconvert_exporter": "python",
   "pygments_lexer": "ipython3",
   "version": "3.8.16"
  },
  "orig_nbformat": 4
 },
 "nbformat": 4,
 "nbformat_minor": 2
}
